Workbook

Sheet Departments
A1: Dept_ID | B1: Department
A2: DEP001 | B2: IT
A3: DEP002 | B3: Finance
A4: DEP003 | B4: HR
A5: DEP004 | B5: Procurement
A6: DEP005 | B6: Operations
A7: DEP006 | B7: Sales
A8: DEP007 | B8: Marketing
A9: DEP008 | B9: Engineering
A10: DEP009 | B10: Legal
A11: DEP010 | B11: Customer Service
A12: DEP011 | B12: Facilities
... A16: DEP015 | B16: Executive

Sheet Employees
A1: Employee_ID | B1: Employee_Name | C1: Department | D1: Role | E1: Approval_Limit
A2: EMP0001 | B2: Kaitlyn Mcknight | C2: Facilities | D2: Analyst | E2: 11556
A3: EMP0002 | B3: Catherine Bates | C3: Cyber Security | D3: Manager | E3: 69196
A4: EMP0003 | B4: Daniel Orozco | C4: Procurement | D4: Specialist | E4: 198061
A5: EMP0004 | B5: Sarah Simmons | C5: Finance | D5: Director | E5: 27790
A6: EMP0005 | B6: Jeffrey Walker | C6: Customer Service | D6: Lead | E6: 13331
A7: EMP0006 | B7: Eric Chang | C7: IT | D7: Analyst | E7: 62314
A8: EMP0007 | B8: Ryan Miller | C8: Procurement | D8: Director | E8: 162815
A9: EMP0008 | B9: Amber Sawyer | C9: IT | D9: Director | E9: 57124
A10: EMP0009 | B10: Alison Brown | C10: Cyber Security | D10: Director | E10: 114974
A11: EMP0010 | B11: Christopher Mcintyre | C11: Procurement | D11: Lead | E11: 159472
A12: EMP0011 | B12: James Coleman | C12: Operations | D12: Analyst | E12: 203916
A13: EMP0012 | B13: Timothy Mathews | C13: Data Analytics | D13: Specialist | E13: 188013
... A101: EMP0100 | B101: Kenneth Hale | C101: Marketing | D101: Manager | E101: 116038

Sheet Suppliers
A1: Supplier_ID | B1: Supplier_Name | C1: Category | D1: Country | E1: Risk_Score
A2: SUP001 | B2: AWS 1 | C2: Software | D2: USA | E2: 10
A3: SUP002 | B3: Google Cloud 2 | C3: Services | D3: UK | E3: 5
A4: SUP003 | B4: Insight 3 | C4: Hardware | D4: Canada | E4: 47
A5: SUP004 | B5: Samsung 4 | C5: Software | D5: UK | E5: 21
A6: SUP005 | B6: Dell 5 | C6: Services | D6: India | E6: 38
A7: SUP006 | B7: Intel 6 | C7: Hardware | D7: Canada | E7: 25
A8: SUP007 | B8: Intel 7 | C8: Services | D8: India | E8: 61
A9: SUP008 | B9: Intel 8 | C9: Cloud | D9: USA | E9: 75
A10: SUP009 | B10: HP 9 | C10: Services | D10: Canada | E10: 59
A11: SUP010 | B11: Dell 10 | C11: Cloud | D11: India | E11: 76
A12: SUP011 | B12: AWS 11 | C12: Services | D12: India | E12: 6
A13: SUP012 | B13: Samsung 12 | C13: Services | D13: Canada | E13: 19
... A51: SUP050 | B51: Google Cloud 50 | C51: Hardware | D51: India | E51: 33

Sheet Items
A1: Item_ID | B1: Item_Name | C1: Category | D1: Standard_Price
A2: ITM0001 | B2: Hardware Item 1 | C2: Hardware | D2: 7591
A3: ITM0002 | B3: Software Item 2 | C3: Software | D3: 5050
A4: ITM0003 | B4: Hardware Item 3 | C4: Hardware | D4: 3702
A5: ITM0004 | B5: Hardware Item 4 | C5: Hardware | D5: 3214
A6: ITM0005 | B6: Software Item 5 | C6: Software | D6: 5428
A7: ITM0006 | B7: Software Item 6 | C7: Software | D7: 1187
A8: ITM0007 | B8: Software Item 7 | C8: Software | D8: 5803
A9: ITM0008 | B9: Service Item 8 | C9: Service | D9: 8396
A10: ITM0009 | B10: Software Item 9 | C10: Software | D10: 8835
A11: ITM0010 | B11: Software Item 10 | C11: Software | D11: 502
A12: ITM0011 | B12: Hardware Item 11 | C12: Hardware | D12: 4329
A13: ITM0012 | B13: Hardware Item 12 | C13: Hardware | D13: 9562
... A201: ITM0200 | B201: Hardware Item 200 | C201: Hardware | D201: 3595

Sheet Module_Spend_Cube
A3: Sum of Total_Amount | C3: Supplier_ID
A4: Department | B4: Item_Category | C4: SUP001 | D4: SUP002 | E4: SUP003 | F4: SUP004 | G4: SUP005 | H4: SUP006 | I4: SUP007 | J4: SUP008 | K4: SUP009 | L4: SUP010 | M4: SUP011 | N4: SUP012 | O4: SUP013 | P4: SUP014 | Q4: SUP015 | R4: SUP016 | S4: SUP017 | T4: SUP018 | U4: SUP019 | V4: SUP020 | W4: SUP021 | X4: SUP022 | Y4: SUP023 | Z4: SUP024 | AA4: SUP025 | AB4: SUP026 | AC4: SUP027 | AD4: SUP028 | AE4: SUP029 | AF4: SUP030 | AG4: SUP031 | AH4: SUP032 | AI4: SUP033 | AJ4: SUP034 | AK4: SUP035 | AL4: SUP036 | AM4: SUP037 | AN4: SUP038 | AO4: SUP039 | AP4: SUP040 | AQ4: SUP041 | AR4: SUP042 | AS4: SUP043 | AT4: SUP044 | AU4: SUP045 | AV4: SUP046 | AW4: SUP047 | AX4: SUP048 | AY4: SUP049 | AZ4: SUP050 | BA4: Grand Total
A5: Customer Service | B5: Hardware | E5: 427959.34 | G5: 258636.92 | H5: 106238.61 | J5: 636400.14 | K5: 596129.68 | M5: 1133872.8 | N5: 579523.94 | O5: 606511.11 | P5: 54159.74 | Q5: 463754.13 | R5: 117871.22 | S5: 544763.66 | U5: 78833.22 | W5: 17549.68 | X5: 19897.49 | Y5: 774146.39 | Z5: 527047.72 | AA5: 519486.1 | AB5: 38987.94 | AC5: 46322.46 | AD5: 274665.64 | AG5: 99278.28 | AH5: 116530.64 | AI5: 489314.35 | AJ5: 8056.84 | AM5: 445901.66 | AN5: 266724.83 | AO5: 45578.73 | AP5: 91621.85 | AQ5: 308140.37 | AR5: 619274.04 | AS5: 89129.09 | AU5: 733963.47 | AW5: 205358.63 | AX5: 107923.74 | AZ5: 311519.1 | BA5: 11761074
A6: Customer Service | B6: Service | C6: 401714.56 | D6: 38360.39 | E6: 107597.21 | F6: 458386.63 | G6: 18452.11 | H6: 53301.33 | I6: 326122.82 | J6: 608981.93 | K6: 406607.96 | L6: 1079493.3 | M6: 674009.22 | N6: 474332.09 | O6: 125487.32 | P6: 308320.42 | Q6: 531445.41 | R6: 298506.92 | S6: 376937.08 | T6: 468778.38 | U6: 12843.61 | W6: 386869.47 | X6: 750473.57 | AA6: 127565.81 | AB6: 52386.07 | AC6: 72381.49 | AD6: 48170.27 | AE6: 197956.25 | AF6: 761484.41 | AG6: 150611.64 | AH6: 126980.29 | AI6: 25124.99 | AJ6: 505572.71 | AK6: 212931.52 | AL6: 346843.07 | AM6: 1150191.4 | AN6: 170765.29 | AO6: 119730.09 | AP6: 145429.25 | AQ6: 76477.84 | AR6: 157944.06 | AT6: 178155.86 | AU6: 42027.57 | AV6: 395543.04 | AX6: 263959.74 | AY6: 469285.2 | AZ6: 17847.14 | BA6: 13722387
A7: Customer Service | B7: Software | C7: 218261.32 | E7: 602858.15 | I7: 174857.57 | J7: 378656.34 | K7: 790542.29 | L7: 492997.85 | N7: 513626.72 | O7: 12210.59 | P7: 297576.17 | Q7: 39864.13 | R7: 291929.88 | S7: 149593.24 | T7: 81020.05 | U7: 41102.55 | V7: 870997.72 | W7: 240179.32 | X7: 203360.75 | AA7: 216475.15 | AB7: 377328.51 | AC7: 4044.78 | AD7: 37339.98 | AE7: 483673.51 | AF7: 559987.96 | AH7: 442219.61 | AJ7: 74938.39 | AK7: 165054.01 | AL7: 223789.55 | AM7: 77257.43 | AN7: 290999.8 | AO7: 150669.69 | AP7: 225381.07 | AQ7: 114937.82 | AT7: 71219.72 | AU7: 82487.87 | AV7: 14309.39 | AY7: 91532.34 | AZ7: 639091.55 | BA7: 9742372.8
A8: Customer Service | B8: (blank) | C8: 753276.17 | D8: 335078.68 | E8: 2093882.9 | F8: 982646.26 | G8: 683330.24 | H8: 1570811.7 | I8: 1216611.5 | J8: 1309937.7 | K8: 1722957.1 | L8: 1615120.1 | M8: 1453694.6 | N8: 3020022.4 | O8: 1299037.6 | P8: 266424.18 | Q8: 2123739 | R8: 1002441.9 | S8: 1595817.2 | T8: 1425538.9 | U8: 1433507.3 | V8: 1307898.6 | W8: 1155242.1 | X8: 2196799.4 | Y8: 936083.42 | Z8: 627945.94 | AA8: 1689196.5 | AB8: 1196831.4 | AC8: 1449318.9 | AD8: 842025.17 | AE8: 1478095.8 | AF8: 1737837.3 | AG8: 2639798.6 | AH8: 1223073.3 | AI8: 763313.94 | AJ8: 894170.62 | AK8: 1271731.3 | AL8: 1905067.3 | AM8: 2195026.6 | AN8: 1008205.6 | AO8: 796799.78 | AP8: 1364791.7 | AQ8: 1530366.6 | AR8: 1086503.8 | AS8: 391044.11 | AT8: 1727181.4 | AU8: 851077.56 | AV8: 577989.33 | AW8: 2186617.9 | AX8: 1201906.1 | AY8: 1454846.7 | AZ8: 1412564.8 | BA8: 67003227
A9: Customer Service Total | C9: 1373252 | D9: 373439.07 | E9: 3232297.6 | F9: 1441032.9 | G9: 960419.27 | H9: 1730351.7 | I9: 1717591.9 | J9: 2933976.1 | K9: 3516237.1 | L9: 3187611.3 | M9: 3261576.6 | N9: 4587505.2 | O9: 2043246.6 | P9: 926480.51 | Q9: 3158802.7 | R9: 1710749.9 | S9: 2667111.2 | T9: 1975337.3 | U9: 1566286.7 | V9: 2178896.3 | W9: 1799840.6 | X9: 3170531.2 | Y9: 1710229.8 | Z9: 1154993.7 | AA9: 2552723.5 | AB9: 1665533.9 | AC9: 1572067.6 | AD9: 1202201.1 | AE9: 2159725.5 | AF9: 3059309.7 | AG9: 2889688.5 | AH9: 1908803.9 | AI9: 1277753.3 | AJ9: 1482738.6 | AK9: 1649716.9 | AL9: 2475699.9 | AM9: 3868377.1 | AN9: 1736695.5 | AO9: 1112778.3 | AP9: 1827223.9 | AQ9: 2029922.6 | AR9: 1863721.9 | AS9: 480173.2 | AT9: 1976557 | AU9: 1709556.5 | AV9: 987841.76 | AW9: 2391976.5 | AX9: 1573789.6 | AY9: 2015664.2 | AZ9: 2381022.6 | BA9: 1.0222906e+08
A10: Cyber Security | B10: Hardware | C10: 418185.47 | E10: 26128.3 | F10: 344991.09 | G10: 123834.15 | H10: 47528.04 | I10: 186064.71 | J10: 172270.88 | K10: 144279.78 | M10: 37934.33 | N10: 381184.92 | O10: 178470.09 | P10: 252450.97 | Q10: 175070.28 | R10: 289819.64 | S10: 86060.56 | T10: 21880.29 | V10: 90668.01 | W10: 1052721 | Y10: 73057.28 | AB10: 280936.79 | AC10: 309946.99 | AE10: 169134.75 | AG10: 624119.58 | AH10: 909301.61 | AI10: 154980.59 | AJ10: 440201.02 | AK10: 38313.6 | AL10: 229159.31 | AM10: 165534.64 | AQ10: 732198.05 | AV10: 604382.19 | AW10: 178905.84 | AX10: 405544.3 | AZ10: 18621.33 | BA10: 9363880.4
A11: Cyber Security | B11: Service | C11: 4324.53 | D11: 47814.39 | E11: 216.23 | F11: 323018.27 | G11: 252512.41 | H11: 172954.04 | J11: 282478.22 | L11: 386775.28 | M11: 85874.12 | O11: 424095.25 | P11: 376506.7 | Q11: 152340.22 | S11: 250575.99 | T11: 253254.72 | U11: 268419.88 | X11: 429053.89 | Y11: 75984.32 | AA11: 555233.18 | AB11: 282630.85 | AD11: 337391.2 | AF11: 89081.7 | AG11: 317032.84 | AH11: 53327.22 | AI11: 169751.9 | AJ11: 189582.74 | AK11: 3728.45 | AL11: 202779.65 | AM11: 34792.86 | AP11: 178142.76 | AQ11: 350250.99 | AR11: 40792.68 | AS11: 488799.8 | AT11: 172432.17 | AU11: 401364.06 | AX11: 356424.32 | AY11: 321144.55 | AZ11: 53956.21 | BA11: 8384838.6
A12: Cyber Security | B12: Software | C12: 204603.17 | D12: 446999.64 | F12: 301248.76 | G12: 2451.2 | H12: 47342.91 | I12: 334168.85 | K12: 196606.73 | L12: 109436.56 | M12: 86786.3 | N12: 141816.32 | O12: 348678.77 | P12: 111336.34 | R12: 257454.54 | S12: 617830.58 | T12: 25348.45 | V12: 430172.78 | W12: 214734.77 | X12: 196053.41 | Y12: 16331.74 | Z12: 84992.53 | AA12: 8068.87 | AB12: 179229.21 | AD12: 201694.87 | AE12: 6917.2 | AF12: 199075 | AG12: 218557.74 | AH12: 427529.62 | AI12: 31844.67 | AJ12: 8891.5 | AK12: 330555.74 | AM12: 456847.8 | AN12: 60385.17 | AP12: 384364.07 | AQ12: 312177.3 | AR12: 99935.03 | AS12: 205245.7 | AT12: 338771.8 | AU12: 342596.96 | AW12: 182886.02 | AX12: 63070.98 | AY12: 740293 | BA12: 8973332.6
A13: Cyber Security | B13: (blank) | C13: 1654902.7 | D13: 254693.52 | E13: 895520.93 | F13: 1800641.3 | G13: 1019209.2 | H13: 2287531.9 | I13: 1104020.8 | J13: 532972.31 | K13: 2153456 | L13: 88861.42 | M13: 1265145.3 | N13: 1249807 | O13: 1061728.4 | P13: 1282862.6 | Q13: 813915.34 | R13: 415753.11 | S13: 877763.41 | T13: 776300.46 | U13: 506348.31 | V13: 1108558.1 | W13: 1468856.2 | X13: 88298.08 | Y13: 1139713.1 | Z13: 820907.55 | AA13: 785310.62 | AB13: 864596.37 | AC13: 538428.81 | AD13: 1307529.8 | AE13: 1550331.3 | AF13: 433152.91 | AG13: 992073.95 | AH13: 1203559.1 | AI13: 1509527.6 | AJ13: 1225480.7 | AK13: 307062.12 | AL13: 792555.99 | AM13: 1026240.5 | AN13: 606284.54 | AO13: 1427758.5 | AP13: 1897107 | AQ13: 1197618.5 | AR13: 1415789 | AS13: 586141.44 | AT13: 801315.99 | AU13: 852462.81 | AV13: 1200348.8 | AW13: 710774.98 | AX13: 547212.8 | AY13: 1900728.7 | AZ13: 709249.91 | BA13: 51056410
A14: Cyber Security Total | C14: 2282015.9 | D14: 749507.55 | E14: 921865.46 | F14: 2769899.4 | G14: 1398007 | H14: 2555356.9 | I14: 1624254.4 | J14: 987721.41 | K14: 2494342.5 | L14: 585073.26 | M14: 1475740 | N14: 1772808.2 | O14: 2012972.5 | P14: 2023156.6 | Q14: 1141325.8 | R14: 963027.29 | S14: 1832230.5 | T14: 1076783.9 | U14: 774768.19 | V14: 1629398.9 | W14: 2736311.9 | X14: 713405.38 | Y14: 1305086.5 | Z14: 905900.08 | AA14: 1348612.7 | AB14: 1607393.2 | AC14: 848375.8 | AD14: 1846615.8 | AE14: 1726383.3 | AF14: 721309.61 | AG14: 2151784.1 | AH14: 2593717.5 | AI14: 1866104.7 | AJ14: 1864155.9 | AK14: 679659.91 | AL14: 1224494.9 | AM14: 1683415.8 | AN14: 666669.71 | AO14: 1427758.5 | AP14: 2459613.9 | AQ14: 2592244.9 | AR14: 1556516.7 | AS14: 1280186.9 | AT14: 1312520 | AU14: 1596423.8 | AV14: 1804731 | AW14: 1072566.8 | AX14: 1372252.4 | AY14: 2962166.2 | AZ14: 781827.45 | BA14: 77778461
A15: Data Analytics | B15: Hardware | C15: 49553.59 | D15: 259639.61 | E15: 149576.2 | F15: 9073.03 | H15: 484701.93 | I15: 9216.14 | J15: 596031.62 | L15: 336311.95 | M15: 38337.57 | O15: 445816.73 | S15: 44177.53 | U15: 538725.43 | W15: 373806.93 | X15: 100430.96 | Y15: 270373.16 | Z15: 39771.48 | AA15: 284453.16 | AC15: 858896.34 | AD15: 190721.08 | AE15: 269632.37 | AI15: 12402.91 | AJ15: 104297.1 | AK15: 34422.32 | AM15: 37778.15 | AN15: 632738.51 | AP15: 175965.98 | AS15: 87004.45 | AW15: 647175.04 | AX15: 83100.75 | BA15: 7164132
A16: Data Analytics | B16: Service | C16: 266771.33 | D16: 9139.04 | F16: 214862.6 | G16: 516701.93 | H16: 447169.28 | I16: 71274.99 | J16: 268819.53 | K16: 260398.87 | M16: 82279.98 | N16: 640178.61 | O16: 121060.5 | P16: 418401.38 | Q16: 2180.64 | R16: 423125.97 | S16: 349415.87 | T16: 172737.38 | V16: 391420.2 | Y16: 204036.2 | AA16: 213953.65 | AB16: 380741.81 | AC16: 380148.6 | AD16: 249389.95 | AE16: 274028.7 | AG16: 316597.58 | AH16: 148333.18 | AI16: 267819.84 | AK16: 49529.7 | AL16: 86879.12 | AM16: 366273.29 | AN16: 678851.45 | AO16: 397984.76 | AP16: 259864.82 | AR16: 178688.35 | AS16: 377052.28 | AU16: 39538.98 | AW16: 106076.54 | AX16: 373802.43 | AZ16: 193718.57 | BA16: 10199248
A17: Data Analytics | B17: Software | C17: 110454.19 | D17: 188829.31 | E17: 15790.61 | F17: 582282.12 | H17: 6637.57 | I17: 49515.74 | J17: 161656.94 | L17: 255223.64 | M17: 31555.39 | O17: 106502.63 | P17: 679645.94 | R17: 439040.57 | S17: 3076.48 | T17: 114518.14 | U17: 68534.43 | Y17: 192441.41 | Z17: 187843.05 | AA17: 537548.74 | AC17: 252277.71 | AH17: 408675.85 | AI17: 109273.75 | AJ17: 339732.54 | AL17: 107651.72 | AN17: 266090.85 | AQ17: 423370.19 | AR17: 37306.41 | AS17: 989358.16 | AU17: 169570.97 | AV17: 68877.31 | AW17: 777641.6 | AY17: 60720.48 | AZ17: 451578.96 | BA17: 8193223.4
A18: Data Analytics | B18: (blank) | C18: 1135904.9 | D18: 1558511.4 | E18: 376992.57 | F18: 767399.86 | G18: 1774861 | H18: 665170.93 | I18: 1542348.7 | J18: 1026709.1 | K18: 634212.36 | L18: 901698.26 | M18: 1459538.8 | N18: 1244866.1 | O18: 636171.51 | P18: 1176296.3 | Q18: 1326452.4 | R18: 1382298.4 | S18: 743469.08 | T18: 891088.34 | U18: 1676520 | V18: 1487190.7 | W18: 1665004.9 | X18: 1196825.3 | Y18: 1343431.1 | Z18: 566169.14 | AA18: 49142.73 | AB18: 1235847.2 | AC18: 730903.09 | AD18: 1779645.6 | AE18: 1079999 | AF18: 605293.73 | AG18: 719741.25 | AH18: 797512.76 | AI18: 1126951.7 | AJ18: 431409.03 | AK18: 2046379.7 | AL18: 1559277.1 | AM18: 1025150.9 | AN18: 1643949.6 | AO18: 810937.76 | AP18: 1887915.8 | AQ18: 687533 | AR18: 1912721.9 | AS18: 904514.61 | AT18: 1403788.5 | AU18: 789110.22 | AV18: 1953214.8 | AW18: 894562.58 | AX18: 1058778.7 | AY18: 1407846.2 | AZ18: 852650.23 | BA18: 56573909
A19: Data Analytics Total | C19: 1562684 | D19: 2016119.4 | E19: 542359.38 | F19: 1573617.6 | G19: 2291562.9 | H19: 1603679.7 | I19: 1672355.5 | J19: 2053217.2 | K19: 894611.23 | L19: 1493233.8 | M19: 1611711.7 | N19: 1885044.7 | O19: 1309551.4 | P19: 2274343.6 | Q19: 1328633 | R19: 2244465 | S19: 1140139 | T19: 1178343.9 | U19: 2283779.9 | V19: 1878610.9 | W19: 2038811.9 | X19: 1297256.2 | Y19: 2010281.9 | Z19: 793783.67 | AA19: 1085098.3 | AB19: 1616589.1 | AC19: 2222225.7 | AD19: 2219756.6 | AE19: 1623660 | AF19: 605293.73 | AG19: 1036338.8 | AH19: 1354521.8 | AI19: 1516448.2 | AJ19: 875438.67 | AK19: 2130331.7 | AL19: 1753807.9 | AM19: 1429202.3 | AN19: 3221630.4 | AO19: 1208922.5 | AP19: 2323746.6 | AQ19: 1110903.2 | AR19: 2128716.7 | AS19: 2357929.5 | AT19: 1403788.5 | AU19: 998220.17 | AV19: 2022092.1 | AW19: 2425455.8 | AX19: 1515681.9 | AY19: 1468566.7 | AZ19: 1497947.8 | BA19: 82130512
A20: Engineering | B20: Hardware | C20: 188292.66 | D20: 430202.77 | E20: 470825.94 | F20: 98889.27 | G20: 461459.27 | I20: 5812.36 | K20: 114875.17 | M20: 112607.44 | N20: 447310.17 | O20: 160806.72 | P20: 521283.99 | Q20: 95042.95 | R20: 198778.02 | S20: 275953.04 | T20: 41250.85 | U20: 180162.25 | V20: 118495.16 | W20: 57548.43 | X20: 563312.74 | Z20: 25571.1 | AB20: 909751.72 | AC20: 124164.76 | AD20: 94751.18 | AE20: 431838.99 | AF20: 605070.52 | AG20: 654003.02 | AH20: 237628.15 | AI20: 467830.96 | AJ20: 320992.1 | AK20: 891186.56 | AL20: 201642.62 | AN20: 77149.8 | AO20: 90231.49 | AP20: 13029.5 | AQ20: 176988.36 | AS20: 201596.59 | AT20: 113334.83 | AU20: 415779.61 | AV20: 313030.82 | AW20: 320092.07 | AX20: 82677.01 | AY20: 303550.23 | AZ20: 108158.8 | BA20: 11722960
A21: Engineering | B21: Service | D21: 7473.41 | E21: 308895.92 | F21: 228860 | G21: 30696.83 | H21: 392769.87 | I21: 278453.05 | J21: 36480.45 | K21: 536884.54 | N21: 169757.87 | O21: 256119.05 | P21: 253929.95 | Q21: 334852.2 | R21: 304928.74 | S21: 102670.86 | T21: 279422.99 | U21: 391679.77 | W21: 242640.93 | X21: 687346.82 | Y21: 519735.7 | Z21: 194647.38 | AA21: 234187.33 | AC21: 607371.99 | AD21: 405809.49 | AE21: 287698.81 | AF21: 611383.44 | AG21: 649903.92 | AH21: 299649.89 | AI21: 312194.63 | AL21: 119565.46 | AM21: 463561.33 | AN21: 940783.22 | AO21: 409803.98 | AP21: 64095.04 | AR21: 273128.08 | AS21: 149753.97 | AT21: 332094.7 | AU21: 297586.77 | AV21: 94966.07 | AX21: 21563.82 | AY21: 434089.05 | AZ21: 418032.39 | BA21: 12985470
A22: Engineering | B22: Software | C22: 469355.38 | D22: 112719.82 | E22: 267743.84 | F22: 291966.86 | G22: 327287.68 | H22: 509917.61 | I22: 352549.06 | K22: 378525.18 | L22: 769623.16 | M22: 2721.2 | N22: 194437.94 | O22: 596650.44 | P22: 290514.53 | Q22: 5814.3 | S22: 921756.43 | T22: 170099.34 | U22: 23664.73 | V22: 313506.97 | W22: 96269.15 | X22: 183589.81 | Z22: 57638.94 | AA22: 976935.37 | AC22: 466076.24 | AE22: 1184218.1 | AG22: 24116.26 | AH22: 30790.92 | AI22: 330423.39 | AJ22: 904570.94 | AK22: 348690.05 | AM22: 338368.28 | AN22: 337686.05 | AO22: 2991.2 | AP22: 279110.3 | AQ22: 464499.28 | AR22: 62505.07 | AS22: 98396.67 | AT22: 147303.69 | AU22: 11712.16 | AV22: 144152.95 | AW22: 489264.47 | AX22: 173215.23 | AY22: 455972.6 | AZ22: 577876.35 | BA22: 14185228
A23: Engineering | B23: (blank) | C23: 2068959.5 | D23: 1298567.5 | E23: 917493.91 | F23: 1665614.3 | G23: 2109934.5 | H23: 1809443.7 | I23: 1241216.5 | J23: 1390629.6 | K23: 874502.07 | L23: 267100.35 | M23: 1126067.2 | N23: 756021.61 | O23: 1309821.6 | P23: 460409.83 | Q23: 1708868.4 | R23: 1885089.3 | S23: 2018303.8 | T23: 1804357.7 | U23: 1376717.9 | V23: 1560502.8 | W23: 949818.13 | X23: 1024159.8 | Y23: 1312497 | Z23: 1201708.2 | AA23: 525709.48 | AB23: 2065183.6 | AC23: 1878274.2 | AD23: 1322765.8 | AE23: 2464094.2 | AF23: 1099357.6 | AG23: 2306639.8 | AH23: 2699514.9 | AI23: 415951.8 | AJ23: 1118385.9 | AK23: 2587722.7 | AL23: 818094.21 | AM23: 2297415.8 | AN23: 1624474.6 | AO23: 2142772.5 | AP23: 1026641.2 | AQ23: 1374153 | AR23: 1209709 | AS23: 1857755.5 | AT23: 2281858.9 | AU23: 900944.93 | AV23: 2392846.6 | AW23: 699203.55 | AX23: 1430729.6 | AY23: 1145869.9 | AZ23: 1931874.5 | BA23: 73755749
A24: Engineering Total | C24: 2726607.6 | D24: 1848963.5 | E24: 1964959.6 | F24: 2285330.4 | G24: 2929378.3 | H24: 2712131.2 | I24: 1878030.9 | J24: 1427110 | K24: 1904787 | L24: 1036723.5 | M24: 1241395.8 | N24: 1567527.6 | O24: 2323397.8 | P24: 1526138.3 | Q24: 2144577.9 | R24: 2388796 | S24: 3318684.2 | T24: 2295130.9 | U24: 1972224.6 | V24: 1992504.9 | W24: 1346276.6 | X24: 2458409.2 | Y24: 1832232.7 | Z24: 1479565.7 | AA24: 1736832.2 | AB24: 2974935.3 | AC24: 3075887.1 | AD24: 1823326.5 | AE24: 4367850 | AF24: 2315811.5 | AG24: 3634663 | AH24: 3267583.9 | AI24: 1526400.8 | AJ24: 2343948.9 | AK24: 3827599.4 | AL24: 1139302.3 | AM24: 3099345.5 | AN24: 2980093.7 | AO24: 2645799.1 | AP24: 1382876.1 | AQ24: 2015640.7 | AR24: 1545342.2 | AS24: 2307502.7 | AT24: 2874592.1 | AU24: 1626023.5 | AV24: 2944996.4 | AW24: 1508560.1 | AX24: 1708185.7 | AY24: 2339481.8 | AZ24: 3035942 | BA24: 1.1264941e+08
A25: Executive | B25: Hardware | C25: 828101.87 | D25: 214921.47 | E25: 869738.99 | G25: 326909.23 | H25: 54033.42 | I25: 314538.54 | J25: 313948.32 | K25: 267457.4 | L25: 191007.38 | P25: 129989.36 | Q25: 561043.18 | R25: 185188.55 | S25: 40859.42 | T25: 273633.14 | U25: 434701.98 | V25: 458099.48 | X25: 42679.43 | Y25: 579697.02 | Z25: 168430.38 | AA25: 374657.04 | AC25: 733360.53 | AD25: 608149.53 | AE25: 320342.65 | AF25: 23296.6 | AG25: 1070319.9 | AH25: 447211.29 | AI25: 346762.32 | AJ25: 1018399.2 | AK25: 435420.95 | AL25: 409357.56 | AM25: 444108.42 | AN25: 366328.24 | AO25: 78195.14 | AP25: 421301.94 | AQ25: 497406.18 | AR25: 580144.02 | AS25: 201228.54 | AU25: 792226.99 | AW25: 275825.93 | AX25: 189431.7 | AY25: 810321.85 | AZ25: 416737.45 | BA25: 17115513
A26: Executive | B26: Service | C26: 195468.97 | D26: 31833 | E26: 243468.22 | F26: 326253.73 | G26: 536360.27 | H26: 389033.23 | I26: 499303.31 | J26: 1113214.6 | K26: 65112.63 | L26: 1222419.6 | M26: 669269.03 | N26: 253419.9 | O26: 494070.87 | P26: 52255.46 | Q26: 12913.25 | R26: 382894.45 | S26: 242771.45 | T26: 940143.66 | U26: 33956.17 | V26: 46769.14 | W26: 158905.74 | X26: 199967.59 | Y26: 56181.35 | Z26: 217047.55 | AA26: 320113.36 | AB26: 181561.84 | AC26: 40015.31 | AD26: 133041.62 | AE26: 459525.97 | AF26: 803159.98 | AG26: 769852.65 | AH26: 591314.91 | AI26: 379277.13 | AJ26: 639229.02 | AK26: 61603.72 | AL26: 190487.73 | AM26: 565456.16 | AN26: 860311.85 | AO26: 187783.46 | AP26: 279591.08 | AQ26: 29558.72 | AS26: 379898.66 | AT26: 185216.27 | AU26: 472815.42 | AV26: 180554.48 | AW26: 870338.78 | AX26: 379555.39 | AY26: 1069001.5 | AZ26: 529364.39 | BA26: 18941663
A27: Executive | B27: Software | C27: 436462.32 | D27: 895716.96 | E27: 31889.95 | F27: 790185.18 | G27: 98295.79 | H27: 1046725.2 | I27: 89755.05 | K27: 377816.32 | L27: 1352193.6 | M27: 535578.36 | N27: 235718.68 | O27: 112855.4 | P27: 490564.02 | Q27: 669993.52 | R27: 399248.59 | S27: 479587.98 | U27: 435107.66 | W27: 556766.15 | X27: 387648.46 | Y27: 635221.28 | Z27: 309088.05 | AA27: 33644.42 | AB27: 82208.56 | AE27: 378712.32 | AF27: 9465.69 | AG27: 221396.4 | AH27: 47449.56 | AI27: 90132.8 | AJ27: 708101.96 | AK27: 561216.7 | AL27: 101946.84 | AM27: 80945.5 | AN27: 234275.42 | AO27: 221925.07 | AP27: 746994.29 | AR27: 10211.93 | AU27: 1175286.3 | AV27: 541641.35 | AW27: 119594.87 | AX27: 207020.87 | AY27: 294821.42 | AZ27: 212916.84 | BA27: 16446328
A28: Executive | B28: (blank) | C28: 1579215.2 | D28: 1909965.8 | E28: 1753733.7 | F28: 2519439.2 | G28: 1302067.8 | H28: 2218322.8 | I28: 1634047.5 | J28: 1706693.3 | K28: 1338818.3 | L28: 1098237.3 | M28: 2429024.2 | N28: 1502533.6 | O28: 2606270.1 | P28: 3794399.6 | Q28: 2355613.9 | R28: 1394353.2 | S28: 1994146.6 | T28: 1753724.8 | U28: 2124424.2 | V28: 1711540.3 | W28: 653192.56 | X28: 2605522.5 | Y28: 1425622.7 | Z28: 2684554.6 | AA28: 2858353.2 | AB28: 1992721.3 | AC28: 2353729.2 | AD28: 3668267.7 | AE28: 1966292.1 | AF28: 1242985.2 | AG28: 2551676.3 | AH28: 1962321.1 | AI28: 1360125 | AJ28: 1221131.3 | AK28: 2445534.4 | AL28: 2181256.4 | AM28: 2285342 | AN28: 2022828 | AO28: 1231816.9 | AP28: 1748852.7 | AQ28: 2131103.2 | AR28: 2073123.9 | AS28: 2386872.5 | AT28: 3499894.9 | AU28: 2254448.4 | AV28: 3149171.6 | AW28: 1917650.3 | AX28: 4257435.8 | AY28: 2872649.8 | AZ28: 1569156.3 | BA28: 1.053002e+08
A29: Executive Total | C29: 3039248.4 | D29: 3052437.2 | E29: 2898830.8 | F29: 3635878.1 | G29: 2263633.1 | H29: 3708114.7 | I29: 2537644.4 | J29: 3133856.2 | K29: 2049204.6 | L29: 3863858 | M29: 3633871.5 | N29: 1991672.1 | O29: 3213196.3 | P29: 4467208.4 | Q29: 3599563.8 | R29: 2361684.8 | S29: 2757365.5 | T29: 2967501.6 | U29: 3028190 | V29: 2216408.9 | W29: 1368864.4 | X29: 3235818 | Y29: 2696722.4 | Z29: 3379120.6 | AA29: 3586768 | AB29: 2256491.7 | AC29: 3127105.1 | AD29: 4409458.8 | AE29: 3124873 | AF29: 2078907.4 | AG29: 4613245.3 | AH29: 3048296.8 | AI29: 2176297.2 | AJ29: 3586861.5 | AK29: 3503775.8 | AL29: 2883048.5 | AM29: 3375852.1 | AN29: 3483743.5 | AO29: 1719720.6 | AP29: 3196740 | AQ29: 2658068.1 | AR29: 2663479.8 | AS29: 2967999.7 | AT29: 3685111.2 | AU29: 4694777.1 | AV29: 3871367.4 | AW29: 3183409.9 | AX29: 5033443.7 | AY29: 5046794.6 | AZ29: 2728175 | BA29: 1.5780371e+08
A30: Facilities | B30: Hardware | C30: 262222.18 | D30: 85052.31 | E30: 255096.82 | G30: 375845.17 | I30: 75774.3 | J30: 484362.92 | K30: 953130.4 | L30: 110310.83 | N30: 332883.84 | P30: 363550.82 | Q30: 182136.3 | R30: 608642.08 | S30: 242480.12 | T30: 106097.91 | V30: 101776.14 | W30: 484655.13 | X30: 632739.45 | Y30: 459801.85 | Z30: 414103.45 | AA30: 317069.31 | AB30: 186886.89 | AD30: 211654.13 | AE30: 124417.67 | AF30: 83314.47 | AH30: 207465.35 | AI30: 655964.27 | AJ30: 140099.79 | AK30: 212022.12 | AL30: 506465.12 | AM30: 230005.71 | AN30: 253371.3 | AP30: 146693.16 | AQ30: 341397.32 | AR30: 304270.42 | AS30: 174000.75 | AU30: 219591.1 | AV30: 236037.34 | AW30: 119331.94 | AX30: 14814.15 | AY30: 419598.19 | AZ30: 169030.04 | BA30: 11804163
A31: Facilities | B31: Service | C31: 853685.16 | E31: 142912.21 | F31: 653566.2 | G31: 684899.55 | H31: 67960.56 | I31: 577822.31 | J31: 322230.58 | M31: 402729.05 | N31: 58789.47 | O31: 649542.61 | P31: 664912.05 | Q31: 197574.6 | S31: 14708.09 | T31: 911607.45 | V31: 41380.53 | W31: 72723.35 | X31: 377392.12 | Z31: 164919.71 | AA31: 87828.99 | AB31: 40432.87 | AC31: 602867.43 | AE31: 1189323.5 | AG31: 140365.35 | AH31: 636089.98 | AI31: 709100.03 | AJ31: 7590.81 | AK31: 1089280.5 | AL31: 469676.89 | AN31: 986892.47 | AO31: 859126.03 | AP31: 177069.07 | AQ31: 274922.77 | AR31: 314282.94 | AS31: 508.17 | AU31: 193976.9 | AV31: 575527.14 | AW31: 87244.42 | AX31: 155.92 | AY31: 49121.05 | AZ31: 280400.44 | BA31: 15631139
A32: Facilities | B32: Software | C32: 25280.62 | D32: 149387.39 | E32: 387864.51 | F32: 47655.67 | G32: 191530.63 | H32: 314195.25 | I32: 316001.86 | J32: 164452.72 | K32: 7458.98 | L32: 53346.34 | M32: 387968.93 | N32: 262940.85 | O32: 424988.16 | P32: 285015.3 | Q32: 251430.04 | R32: 177898.83 | S32: 266259.92 | T32: 681835.81 | V32: 27366.41 | W32: 807893.59 | X32: 492585.28 | Y32: 251819.33 | Z32: 36163.67 | AA32: 214189.18 | AB32: 122267.49 | AC32: 137070.45 | AD32: 88353.31 | AE32: 365084.4 | AG32: 114717.42 | AH32: 47732.95 | AI32: 275741.75 | AJ32: 510857.43 | AK32: 721185.44 | AL32: 244132.81 | AM32: 246518.53 | AN32: 492884.03 | AO32: 5610.34 | AP32: 24738.46 | AQ32: 175060.13 | AR32: 685209.8 | AS32: 171427.42 | AT32: 235174.51 | AU32: 306087.5 | AV32: 443201.5 | AW32: 162965.32 | AX32: 947089.01 | AY32: 541623.22 | AZ32: 529722.07 | BA32: 13819985
A33: Facilities | B33: (blank) | C33: 1388708 | D33: 1313268.9 | E33: 1315240.2 | F33: 1847971.4 | G33: 1728941.9 | H33: 1136188.7 | I33: 1665370.9 | J33: 1432145 | K33: 955728.19 | L33: 444157.24 | M33: 1444738.6 | N33: 1467429.2 | O33: 1546232.2 | P33: 1344902.4 | Q33: 2872204.8 | R33: 1293004 | S33: 1751742 | T33: 2244922.4 | U33: 1639063.3 | V33: 1790030.2 | W33: 1238403.6 | X33: 1891132.8 | Y33: 2591951.2 | Z33: 1160275.2 | AA33: 1366294.9 | AB33: 1697479.9 | AC33: 1712731.9 | AD33: 963027.65 | AE33: 2538175.4 | AF33: 3098965.1 | AG33: 1743839.2 | AH33: 1792163.2 | AI33: 1499280.5 | AJ33: 1307531.5 | AK33: 2087131.2 | AL33: 473515.78 | AM33: 1285490.4 | AN33: 2165353.4 | AO33: 1780162.2 | AP33: 2097760.8 | AQ33: 1024444.6 | AR33: 1367418.4 | AS33: 2454943.1 | AT33: 2142780.6 | AU33: 2294566.8 | AV33: 1595397.6 | AW33: 1568308 | AX33: 1588644.9 | AY33: 2125219 | AZ33: 2297533.5 | BA33: 83571912
A34: Facilities Total | C34: 2529895.9 | D34: 1547708.6 | E34: 2101113.7 | F34: 2549193.3 | G34: 2981217.2 | H34: 1518344.5 | I34: 2634969.4 | J34: 2403191.3 | K34: 1916317.6 | L34: 607814.41 | M34: 2235436.6 | N34: 2122043.4 | O34: 2620762.9 | P34: 2658380.6 | Q34: 3503345.8 | R34: 2079544.9 | S34: 2275190.1 | T34: 3944463.6 | U34: 1639063.3 | V34: 1960553.3 | W34: 2603675.7 | X34: 3393849.7 | Y34: 3303572.4 | Z34: 1775462.1 | AA34: 1985382.3 | AB34: 2047067.1 | AC34: 2452669.8 | AD34: 1263035.1 | AE34: 4217000.9 | AF34: 3182279.6 | AG34: 1998921.9 | AH34: 2683451.5 | AI34: 3140086.5 | AJ34: 1966079.5 | AK34: 4109619.2 | AL34: 1693790.6 | AM34: 1762014.6 | AN34: 3898501.2 | AO34: 2644898.6 | AP34: 2446261.5 | AQ34: 1815824.9 | AR34: 2671181.5 | AS34: 2800879.4 | AT34: 2377955.1 | AU34: 3014222.3 | AV34: 2850163.6 | AW34: 1937849.7 | AX34: 2550703.9 | AY34: 3135561.4 | AZ34: 3276686.1 | BA34: 1.248272e+08
A35: Finance | B35: Hardware | C35: 284716.74 | D35: 157321.95 | F35: 31755.33 | G35: 454250.02 | H35: 395373.97 | J35: 220803.86 | K35: 371136.18 | L35: 96396.67 | N35: 739507.58 | P35: 586003.35 | Q35: 639873.94 | R35: 22691.62 | T35: 119155.6 | U35: 185524.66 | V35: 406967.95 | W35: 41423.62 | X35: 824782.12 | Y35: 191937.92 | AB35: 935449.19 | AC35: 288560.98 | AD35: 213688.36 | AF35: 70435.62 | AG35: 508800.92 | AJ35: 304154.62 | AK35: 99213.72 | AL35: 85898.77 | AM35: 405093.59 | AN35: 8812.15 | AO35: 341113.7 | AP35: 115790.08 | AR35: 120584.82 | AS35: 477870.15 | AT35: 533708.23 | AU35: 32000.44 | AV35: 270226.73 | AW35: 364213.47 | AX35: 414668.58 | AY35: 343144.08 | AZ35: 224744.09 | BA35: 11927795
A36: Finance | B36: Service | C36: 394494.24 | D36: 802577.84 | H36: 23928.27 | I36: 61735.64 | J36: 376421.01 | K36: 135318.76 | L36: 668666.2 | M36: 352999.09 | N36: 5375.03 | O36: 406359.26 | P36: 213881.45 | Q36: 433325.55 | R36: 265831.05 | S36: 341510.43 | T36: 485020.41 | U36: 877335.09 | V36: 193006.88 | X36: 804058.94 | Y36: 17274.72 | Z36: 546881.49 | AA36: 580818.99 | AB36: 408290.47 | AC36: 511476 | AD36: 62900.13 | AE36: 626654.3 | AF36: 471537.73 | AG36: 97074.65 | AH36: 705926.98 | AI36: 101435.63 | AJ36: 13879.4 | AL36: 484417.48 | AM36: 264321.97 | AN36: 375413.46 | AO36: 351440.54 | AP36: 98616.74 | AQ36: 909853.49 | AS36: 45134.52 | AT36: 331203.65 | AU36: 423728.7 | AV36: 609159.54 | AW36: 394896.8 | AX36: 443757.16 | AY36: 43999.31 | AZ36: 99908.22 | BA36: 15861847
A37: Finance | B37: Software | C37: 565298.25 | D37: 204318.06 | E37: 162036.14 | F37: 310276.66 | G37: 10329.67 | H37: 587035.06 | I37: 171380.01 | J37: 1003904.9 | K37: 1902.28 | L37: 25769.03 | M37: 24946.91 | N37: 361063.77 | O37: 327443.88 | P37: 683835.89 | Q37: 40944.41 | R37: 98985.28 | S37: 613102 | T37: 296923.32 | U37: 122786.95 | V37: 242887.95 | W37: 315316.11 | X37: 120530.18 | Z37: 186901.77 | AA37: 189816.47 | AB37: 877542.13 | AD37: 378283.39 | AE37: 236863.5 | AF37: 847784.9 | AH37: 406308 | AI37: 199476.42 | AJ37: 45449.39 | AL37: 397105.59 | AM37: 369600.8 | AN37: 2927.12 | AO37: 359979.99 | AP37: 55614.62 | AQ37: 655181.4 | AR37: 82592.34 | AS37: 15978.66 | AT37: 381279.09 | AU37: 159923.49 | AV37: 132259.87 | AW37: 40320.26 | AX37: 570962.84 | AY37: 569656.25 | AZ37: 468833.66 | BA37: 13921659
A38: Finance | B38: (blank) | C38: 1447955.4 | D38: 1848396.4 | E38: 1422360 | F38: 2599352.7 | G38: 1467689.3 | H38: 1508084.5 | I38: 1946551.8 | J38: 1815367.5 | K38: 1568712.7 | L38: 1989948.6 | M38: 3494228.9 | N38: 1494431.2 | O38: 1634667 | P38: 1414817 | Q38: 2492829.1 | R38: 2663761.6 | S38: 943611.13 | T38: 1693238.2 | U38: 1878961.4 | V38: 1855115.4 | W38: 893449.62 | X38: 1923396.3 | Y38: 2501650.7 | Z38: 1855562.6 | AA38: 1657432.9 | AB38: 2090251.2 | AC38: 1275849 | AD38: 1115524.8 | AE38: 1266816.3 | AF38: 1973108.2 | AG38: 1563384.6 | AH38: 3492491.6 | AI38: 2740637.2 | AJ38: 1404553.6 | AK38: 1640518.5 | AL38: 2677307 | AM38: 2306367 | AN38: 1065591.7 | AO38: 1393089.4 | AP38: 1878280 | AQ38: 2027633.5 | AR38: 2208017.9 | AS38: 381080.79 | AT38: 2852962.5 | AU38: 1330260.9 | AV38: 1112186.5 | AW38: 1573351.7 | AX38: 1492018.2 | AY38: 1053110.7 | AZ38: 1956435.6 | BA38: 89882400
A39: Finance Total | C39: 2692464.6 | D39: 3012614.3 | E39: 1584396.1 | F39: 2941384.7 | G39: 1932269 | H39: 2514421.8 | I39: 2179667.5 | J39: 3416497.3 | K39: 2077069.9 | L39: 2780780.5 | M39: 3872174.9 | N39: 2600377.6 | O39: 2368470.1 | P39: 2898537.6 | Q39: 3606973 | R39: 3051269.6 | S39: 1898223.6 | T39: 2594337.5 | U39: 3064608.1 | V39: 2697978.2 | W39: 1250189.3 | X39: 3672767.6 | Y39: 2710863.4 | Z39: 2589345.9 | AA39: 2428068.4 | AB39: 4311533 | AC39: 2075886 | AD39: 1770396.7 | AE39: 2130334.1 | AF39: 3362866.5 | AG39: 2169260.1 | AH39: 4604726.6 | AI39: 3041549.2 | AJ39: 1768037 | AK39: 1739732.2 | AL39: 3644728.9 | AM39: 3345383.4 | AN39: 1452744.4 | AO39: 2445623.7 | AP39: 2148301.5 | AQ39: 3592668.4 | AR39: 2411195 | AS39: 920064.12 | AT39: 4099153.4 | AU39: 1945913.5 | AV39: 2123832.6 | AW39: 2372782.2 | AX39: 2921406.8 | AY39: 2009910.3 | AZ39: 2749921.5 | BA39: 1.315937e+08
A40: HR | B40: Hardware | C40: 160147.07 | E40: 154026.72 | G40: 19229.51 | J40: 694245.15 | K40: 124116.36 | P40: 46403.76 | Q40: 309960.56 | R40: 347179.1 | U40: 19873.16 | V40: 160780.91 | W40: 492693.64 | Z40: 223866.2 | AA40: 49703.6 | AB40: 58548.07 | AC40: 354649.13 | AD40: 34224.25 | AF40: 251842.9 | AH40: 95685.95 | AK40: 632218.99 | AM40: 287126.59 | AO40: 144327.19 | AP40: 15447.43 | AQ40: 91198.57 | AT40: 248897.93 | AU40: 126738.4 | AW40: 361524.21 | AX40: 85461.45 | AZ40: 39479.29 | BA40: 5629596.1
A41: HR | B41: Service | C41: 105733.12 | E41: 14603.16 | F41: 307558.43 | G41: 93169.98 | H41: 628136.08 | I41: 4326.13 | J41: 24098.78 | M41: 227083.35 | O41: 56359.71 | P41: 364572.88 | Q41: 1187.9 | T41: 366053.57 | V41: 288591.52 | Z41: 545418.69 | AB41: 454917.68 | AD41: 95679.74 | AE41: 99917.71 | AH41: 271358.31 | AJ41: 66869.45 | AM41: 28887.96 | AP41: 491823.61 | AQ41: 666766.14 | AS41: 583464.19 | AT41: 84455.53 | AV41: 327792.48 | AW41: 151320.73 | AX41: 473085.64 | AY41: 129304.83 | BA41: 6952537.3
A42: HR | B42: Software | C42: 39450.87 | D42: 119706.74 | F42: 263763.35 | G42: 41153.42 | H42: 200807 | L42: 14169.45 | O42: 7787.42 | Q42: 291280.75 | R42: 243949.21 | T42: 307071.07 | U42: 17124.96 | V42: 322384.64 | W42: 117611.43 | X42: 109109.92 | Y42: 313442.5 | Z42: 183485.23 | AA42: 127299.41 | AF42: 392603.12 | AH42: 27922.21 | AI42: 22817.97 | AJ42: 345834.97 | AM42: 505769.86 | AN42: 141183.6 | AO42: 175488.97 | AR42: 2825.76 | AV42: 291616.21 | AW42: 55556.11 | AZ42: 7160.79 | BA42: 4688376.9
...

Sheet Module_Pareto_Audit
A3: Supplier ID | B3: Total Spend | C3: Cumulative %
A4: SUP032 | B4: 32024762 | C4: 0.023416628
A5: SUP044 | B5: 31975741 | C5: 0.046797411
A6: SUP048 | B6: 31837576 | C6: 0.070077167
A7: SUP015 | B7: 31149056 | C7: 0.092853476
A8: SUP006 | B8: 30567491 | C8: 0.11520454
A9: SUP029 | B9: 30505701 | C9: 0.13751043
A10: SUP037 | B10: 30280738 | C10: 0.15965182
A11: SUP022 | B11: 30124314 | C11: 0.18167883
A12: SUP013 | B12: 29645503 | C12: 0.20335573
A13: SUP049 | B13: 29599667 | C13: 0.22499912
A14: SUP018 | B14: 29514070 | C14: 0.24657992
A15: SUP001 | B15: 29163836 | C15: 0.26790463
... A53: SUP039 | B53: 22369546 | C53: 1
A54: Grand Total | B54: 1.3676078e+09

Sheet Distribution_Audit
A1: Approval_Status | B1: Approved
A3: Row Labels | B3: Average | C3: Max | D3: StdDev | E3: Supplier's Count
A4: Hardware | B4: 140305.32 | C4: 517462.68 | D4: 108389.79 | E4: 975
A5: Service | B5: 142151.9 | C5: 554122.01 | D5: 121646.12 | E5: 1181
A6: Software | B6: 126798.55 | C6: 527569.75 | D6: 111287.18 | E6: 1110
A7: Grand Total | B7: 136382.57 | C7: 554122.01 | D7: 114487.1 | E7: 3266

Sheet Maverick_Leakage
A3: Sum of Total_Amount | B3: Column Labels
A4: Row Labels | B4: Approved | C4: Pending | D4: Rejected | E4: Grand Total | G4: Category | H4: Approved Spend | I4: Maverick Spend | J4: % Leakage Rate
A5: Hardware | B5: 1.3679769e+08 | E5: 1.3679769e+08 | G5: Hardware | H5: =GETPIVOTDATA("Total_Amount",$A$3,"Approval_Status","Approved","Item_Category","Hardware") -> 1.3679769e+08 | I5: =GETPIVOTDATA("Total_Amount",$A$3,"Approval_Status","Pending","Item_Category","Hardware")+GETPIVOTDATA("Total_Amount",$A$3,"Approval_Status","Rejected","Item_Category","Hardware") -> 0 | J5: =I5/(GETPIVOTDATA("Total_Amount",$A$3,"Approval_Status","Approved","Item_Category","Hardware")+I5) -> 0
A6: Service | B6: 1.678814e+08 | C6: 519549.31 | D6: 266934.16 | E6: 1.6866788e+08 | G6: Servoice | H6: =GETPIVOTDATA("Total_Amount",$A$3,"Approval_Status","Approved","Item_Category","Service") -> 1.678814e+08 | I6: =GETPIVOTDATA("Total_Amount",$A$3,"Approval_Status","Pending","Item_Category","Service")+GETPIVOTDATA("Total_Amount",$A$3,"Approval_Status","Rejected","Item_Category","Service") -> 786483.47 | J6: =I6/(GETPIVOTDATA("Total_Amount",$A$3,"Approval_Status","Approved","Item_Category","Service")+I6)*100 -> 0.46629119
A7: Software | B7: 1.4074639e+08 | C7: 252209.74 | D7: 53701.13 | E7: 1.410523e+08 | G7: Software | H7: =GETPIVOTDATA("Total_Amount",$A$3,"Approval_Status","Approved","Item_Category","Software") -> 1.4074639e+08 | I7: =GETPIVOTDATA("Total_Amount",$A$3,"Approval_Status","Pending","Item_Category","Software")+GETPIVOTDATA("Total_Amount",$A$3,"Approval_Status","Rejected","Item_Category","Software") -> 305910.87 | J7: =I7/(GETPIVOTDATA("Total_Amount",$A$3,"Approval_Status","Approved","Item_Category","Software")+I7)*100 -> 0.21687762
A8: Grand Total | B8: 4.4542548e+08 | C8: 771759.05 | D8: 320635.29 | E8: 4.4651787e+08 | G8: Total | H8: =GETPIVOTDATA("Total_Amount",$A$3,"Approval_Status","Approved") -> 4.4542548e+08 | I8: =GETPIVOTDATA("Total_Amount",$A$3,"Approval_Status","Pending")+GETPIVOTDATA("Total_Amount",$A$3,"Approval_Status","Rejected") -> 1092394.3 | J8: =I8/(GETPIVOTDATA("Total_Amount",$A$3,"Approval_Status","Approved")+I8)*100 -> 0.24464739

Sheet Purchase_Orders
A1: PO_Number | B1: PO_Date | C1: Employee_ID | D1: Department | E1: Supplier_ID | F1: Item_ID | G1: Quantity | H1: Unit_Price | I1: Total_Amount | J1: Order_Status | K1: Lead_Time | L1: Item_Category
A2: PO000001 | B2: 45918 | C2: EMP0084 | D2: Operations | E2: SUP002 | F2: ITM0026 | G2: 18 | H2: 5542.88 | I2: 99771.86 | J2: Rejected | K2: 41 | L2: =_xlfn.XLOOKUP(F2, Items!$A:$A, Items!$C:$C, "Check Item ID", 0) -> Service
A3: PO000002 | B3: 45132 | C3: EMP0094 | D3: Procurement | E3: SUP006 | F3: ITM0146 | G3: 13 | H3: 9282.65 | I3: 120674.41 | J3: Pending | K3: 14 | L3: =_xlfn.XLOOKUP(F3, Items!$A:$A, Items!$C:$C, "Check Item ID", 0) -> Service
A4: PO000003 | B4: 44955 | C4: EMP0082 | D4: Executive | E4: SUP013 | F4: ITM0046 | G4: 46 | H4: 7881.9 | I4: 362567.24 | J4: Pending | K4: 5 | L4: =_xlfn.XLOOKUP(F4, Items!$A:$A, Items!$C:$C, "Check Item ID", 0) -> Service
A5: PO000004 | B5: 45525 | C5: EMP0069 | D5: Data Analytics | E5: SUP028 | F5: ITM0023 | G5: 45 | H5: 3714.72 | I5: 167162.3 | J5: Rejected | K5: 34 | L5: =_xlfn.XLOOKUP(F5, Items!$A:$A, Items!$C:$C, "Check Item ID", 0) -> Service
A6: PO000005 | B6: 44952 | C6: EMP0053 | D6: HR | E6: SUP046 | F6: ITM0044 | G6: 37 | H6: 6816.48 | I6: 252209.74 | J6: Pending | K6: 31 | L6: =_xlfn.XLOOKUP(F6, Items!$A:$A, Items!$C:$C, "Check Item ID", 0) -> Software
A7: PO000006 | B7: 45304 | C7: EMP0019 | D7: Engineering | E7: SUP033 | F7: ITM0071 | G7: 4 | H7: 9076.92 | I7: 36307.66 | J7: Pending | K7: 10 | L7: =_xlfn.XLOOKUP(F7, Items!$A:$A, Items!$C:$C, "Check Item ID", 0) -> Service
A8: PO000007 | B8: 45747 | C8: EMP0032 | D8: Executive | E8: SUP048 | F8: ITM0132 | G8: 32 | H8: 1678.16 | I8: 53701.13 | J8: Rejected | K8: 6 | L8: =_xlfn.XLOOKUP(F8, Items!$A:$A, Items!$C:$C, "Check Item ID", 0) -> Software
A9: PO000008 | B9: 45232 | C9: EMP0006 | D9: IT | E9: SUP026 | F9: ITM0142 | G9: 37 | H9: 3743.5 | I9: 138509.49 | J9: Approved | K9: 18 | L9: =_xlfn.XLOOKUP(F9, Items!$A:$A, Items!$C:$C, "Check Item ID", 0) -> Software
A10: PO000009 | B10: 45779 | C10: EMP0074 | D10: IT | E10: SUP016 | F10: ITM0142 | G10: 39 | H10: 3394.14 | I10: 132371.33 | J10: Rejected | K10: 17 | L10: =_xlfn.XLOOKUP(F10, Items!$A:$A, Items!$C:$C, "Check Item ID", 0) -> Software
A11: PO000010 | B11: 45706 | C11: EMP0036 | D11: Executive | E11: SUP046 | F11: ITM0010 | G11: 29 | H11: 563.52 | I11: 16342.1 | J11: Pending | K11: 40 | L11: =_xlfn.XLOOKUP(F11, Items!$A:$A, Items!$C:$C, "Check Item ID", 0) -> Software
A12: PO000011 | B12: 45552 | C12: EMP0018 | D12: Operations | E12: SUP005 | F12: ITM0106 | G12: 37 | H12: 5758.76 | I12: 213074.29 | J12: Rejected | K12: 9 | L12: =_xlfn.XLOOKUP(F12, Items!$A:$A, Items!$C:$C, "Check Item ID", 0) -> Software
A13: PO000012 | B13: 45359 | C13: EMP0009 | D13: Cyber Security | E13: SUP006 | F13: ITM0075 | G13: 17 | H13: 2784.88 | I13: 47342.91 | J13: Approved | K13: 18 | L13: =_xlfn.XLOOKUP(F13, Items!$A:$A, Items!$C:$C, "Check Item ID", 0) -> Software
... A10001: PO010000 | B10001: 45733 | C10001: EMP0099 | D10001: Finance | E10001: SUP004 | F10001: ITM0116 | G10001: 29 | H10001: 851.31 | I10001: 24687.98 | J10001: Approved | K10001: 44 | L10001: =_xlfn.XLOOKUP(F10001, Items!$A:$A, Items!$C:$C, "Check Item ID", 0) -> Hardware
